Workbook

Sheet Productos
A1: SKU | B1: Nombre | C1: Categorias | D1: SubCat1 | E1: Foto(s) | F1: Stock | G1: Precio | H1: Padre Id | I1: Hijo Id
A2: 04.08.0014-RJ | B2: 04.08.0014-RJ - CABLE UNILAY THHN ROJO # 14 100MTS ELECTROCABLE | C2: Material Eléctrico | D2: Cables | E2: https://res.cloudinary.com/riqra/image/upload/v1629483021/sellers/megaproductos/products/kt3wq49hob2irnir24dr.png | F2: 0 | G2: 33.67 | H2: =VLOOKUP(C2,Categorias!B:C,2,FALSE) -> 694 | I2: =VLOOKUP(D2,SubCategorias!B:C,2,FALSE) -> 1
A3: 110006209 | B3: 110006209 - CERAMICA PISO BOTTICCINO HUESO SEMI/MATE 45X45 (2.03) PL10 CELIMA | C3: Acabados | D3: Ceramica de piso | E3: https://res.cloudinary.com/riqra/image/upload/v1628261474/sellers/megaproductos/products/ftrgirohhrzto4ytborg.png | F3: 0 | G3: 8.64 | H3: =VLOOKUP(C3,Categorias!B:C,2,FALSE) -> 690 | I3: =VLOOKUP(D3,SubCategorias!B:C,2,FALSE) -> 0
A4: 111000 | B4: 111000 - SIKA 2 DE 2KG | C4: Construcción | D4: Impermeabilizantes | E4: https://res.cloudinary.com/riqra/image/upload/v1629394482/sellers/megaproductos/products/f0zwcp1b3amfoyblvpqh.png | F4: 22 | G4: 11.10 | H4: =VLOOKUP(C4,Categorias!B:C,2,FALSE) -> 703 | I4: =VLOOKUP(D4,SubCategorias!B:C,2,FALSE) -> 0
A5: 123662 | B5: 123662 - EMPASTE INTERIOR BLANCO 10KG + RESINA SIKA | C5: Pinturas y complementos | D5: Empastes | E5: https://res.cloudinary.com/riqra/image/upload/v1628722030/sellers/megaproductos/products/nwqsemsiv9mzvbj7zeaj.png | F5: 0 | G5: 9.35 | H5: =VLOOKUP(C5,Categorias!B:C,2,FALSE) -> 705 | I5: =VLOOKUP(D5,SubCategorias!B:C,2,FALSE) -> 0
A6: 15000102 | B6: 15000102 - INCASOLD #6 ROJO 100MTS INCABLE | C6: Material Eléctrico | D6: Cables | E6: https://res.cloudinary.com/riqra/image/upload/v1629739414/sellers/megaproductos/products/zg0ayfy9sxmajitvfxss.png | F6: 0 | G6: 248.67 | H6: =VLOOKUP(C6,Categorias!B:C,2,FALSE) -> 694 | I6: =VLOOKUP(D6,SubCategorias!B:C,2,FALSE) -> 1
A7: 15000201 | B7: 15000201 - INCASOLD #4 NEGRO 100MTS INCABLE | C7: Material Eléctrico | D7: Cables | E7: https://res.cloudinary.com/riqra/image/upload/v1629739392/sellers/megaproductos/products/og7vycn18wpmodimyxpw.png | F7: 1 | G7: 397.87 | H7: =VLOOKUP(C7,Categorias!B:C,2,FALSE) -> 694 | I7: =VLOOKUP(D7,SubCategorias!B:C,2,FALSE) -> 1
A8: 20021002118 | B8: 20021002118 - BROCHA MULTIUSO 6" WILSON | C8: Pinturas y complementos | D8: Brochas | E8: https://res.cloudinary.com/riqra/image/upload/v1628721066/sellers/megaproductos/products/y190zexeog3be27mbuwn.png | F8: 0 | G8: 11.91 | H8: =VLOOKUP(C8,Categorias!B:C,2,FALSE) -> 705 | I8: =VLOOKUP(D8,SubCategorias!B:C,2,FALSE) -> 0
A9: 23200101-NE | B9: 23200101-NE - CABLE FLEXIBLE #14 THHN/THWN NEGRO 100MTS INCABLE | C9: Material Eléctrico | D9: Cables | E9: https://res.cloudinary.com/riqra/image/upload/v1629738506/sellers/megaproductos/products/efjkcwpriklzifaii6gy.png | F9: 238 | G9: 32.95 | H9: =VLOOKUP(C9,Categorias!B:C,2,FALSE) -> 694 | I9: =VLOOKUP(D9,SubCategorias!B:C,2,FALSE) -> 1
A10: 4010146503 | B10: 4010146503 - GUANTES MASTER REVESTIDO NARANJA CORRUGADO T/M | C10: Seguridad Industrial | D10: Guantes | E10: https://res.cloudinary.com/riqra/image/upload/v1629739993/sellers/megaproductos/products/hzo5mt2bdu2bw25ytk1w.png | F10: 102 | G10: 2.58 | H10: =VLOOKUP(C10,Categorias!B:C,2,FALSE) -> 704 | I10: =VLOOKUP(D10,SubCategorias!B:C,2,FALSE) -> 0
A11: 44900701 | B11: 44900701 - CABLE CONCENTRICO THHN 2X14 100MTS INCABLE | C11: Material Eléctrico | D11: Otros | E11: https://res.cloudinary.com/riqra/image/upload/v1629738163/sellers/megaproductos/products/n83k8deaovil3wscwuib.png | F11: 3 | G11: 87.15 | H11: =VLOOKUP(C11,Categorias!B:C,2,FALSE) -> 694 | I11: =VLOOKUP(D11,SubCategorias!B:C,2,FALSE) -> 0
A12: OSP-200 | B12: OSP-200 - ABRAZADERA DE UN HUECO 2" EMT" | C12: Material Eléctrico | D12: Tubería Conduit Metálica (EMT) | E12: https://res.cloudinary.com/riqra/image/upload/v1629483480/sellers/megaproductos/products/v5ougnf9ssd5llkh9s3g.png | F12: 1525 | G12: 0.38 | H12: =VLOOKUP(C12,Categorias!B:C,2,FALSE) -> 694 | I12: =VLOOKUP(D12,SubCategorias!B:C,2,FALSE) -> 0
A13: TC0409 | B13: TC0409 - PALA CARBONERA C/MANGO CORTO TOOLCRAFT | C13: Herramientas Manuales | D13: Palas | E13: https://res.cloudinary.com/riqra/image/upload/v1629413504/sellers/megaproductos/products/clnnnfvkb96i8k7w9jys.png | F13: 0 | G13: 11.10 | H13: =VLOOKUP(C13,Categorias!B:C,2,FALSE) -> 741 | I13: =VLOOKUP(D13,SubCategorias!B:C,2,FALSE) -> 0
... A4673: 9.04E+05 | B4673: 903916E0 - CABO IDEAL 9/16 AZUL C/C (17KG APROX) PLASTIEMPAQUES | C4673: Ferretería | D4673: Cabos|Ferretería | E4673: https://res.cloudinary.com/riqra/image/upload/v1635877143/sellers/10/yjk5pyjumi7rg1bolgsa.png|https://res.cloudinary.com/riqra/image/upload/v1635877118/sellers/7/qmmck65lphnvqur2pmzj.png|https://res.cloudinary.com/riqra/image/upload/v1635877143/sellers/11/najqurzx50iqixwk9wcu.png | F4673: 5.22 | G4673: 5.09 | H4673: =VLOOKUP(C4673,Categorias!B:C,2,FALSE) -> 742 | I4673: =VLOOKUP(D4673,SubCategorias!B:C,2,FALSE) -> 0
A4674: 7.86E+12 | B4674: 7860693724204 - # BROCHA PRIMA 1" WILSON | E4674: https://res.cloudinary.com/riqra/image/upload/v1534706090/saas/resources/placeholders/product.png|https://res.cloudinary.com/riqra/image/upload/v1534706090/saas/resources/placeholders/product.png|https://res.cloudinary.com/riqra/image/upload/v1534706090/saas/resources/placeholders/product.png|https://res.cloudinary.com/riqra/image/upload/v1534706090/saas/resources/placeholders/product.png|https://res.cloudinary.com/riqra/image/upload/v1534706090/saas/resources/placeholders/product.png|https://res.cloudinary.com/riqra/image/upload/v1534706090/saas/resources/placeholders/product.png|https://res.cloudinary.com/riqra/image/upload/v1534706090/saas/resources/placeholders/product.png|https://res.cloudinary.com/riqra/image/upload/v1534706090/saas/resources/placeholders/product.png|https://res.cloudinary.com/riqra/image/upload/v1534706090/saas/resources/placeholders/product.png|https://res.cloudinary.com/riqra/image/upload/v1534706090/saas/resources/placeholders/product.png|https://res.cloudinary.com/riqra/image/upload/v1534706090/saas/resources/placeholders/product.png|https://res.cloudinary.com/riqra/image/upload/v1534706090/saas/resources/placeholders/product.png|https://res.cloudinary.com/riqra/image/upload/v1534706090/saas/resources/placeholders/product.png|https://res.cloudinary.com/riqra/image/upload/v1534706090/saas/resources/placeholders/product.png|https://res.cloudinary.com/riqra/image/upload/v1534706090/saas/resources/placeholders/product.png|https://res.cloudinary.com/riqra/image/upload/v1534706090/saas/resources/placeholders/product.png|https://res.cloudinary.com/riqra/image/upload/v1534706090/saas/resources/placeholders/product.png|https://res.cloudinary.com/riqra/image/upload/v1534706090/saas/resources/placeholders/product.png|https://res.cloudinary.com/riqra/image/upload/v1534706090/saas/resources/placeholders/product.png|https://res.cloudinary.com/riqra/image/upload/v1534706090/saas/resources/placeholders/product.png|https://res.cloudinary.com/riqra/image/upload/v1534706090/saas/resources/placeholders/product.png|https://res.cloudinary.com/riqra/image/upload/v1534706090/saas/resources/placeholders/product.png | F4674: 246 | G4674: 2.72 | H4674: =VLOOKUP(C4674,Categorias!B:C,2,FALSE) -> #N/A | I4674: =VLOOKUP(D4674,SubCategorias!B:C,2,FALSE) -> #N/A
A4675: 9.03E+12 | B4675: 9031040000000 - # CABO IDEAL AZUL 1/4. C/C (17KG APROX) PLASTIEMPAQUES | E4675: https://res.cloudinary.com/riqra/image/upload/v1534706090/saas/resources/placeholders/product.png | F4675: 0 | G4675: 4.27 | H4675: =VLOOKUP(C4675,Categorias!B:C,2,FALSE) -> #N/A | I4675: =VLOOKUP(D4675,SubCategorias!B:C,2,FALSE) -> #N/A
A4676: 9.04E+12 | B4676: 9035160000000 - CABO IDEAL AZUL 5/16. C/C (17KG APROX) PLASTIEMPAQUES | E4676: https://res.cloudinary.com/riqra/image/upload/v1534706090/saas/resources/placeholders/product.png | F4676: 32.5 | G4676: 4.27 | H4676: =VLOOKUP(C4676,Categorias!B:C,2,FALSE) -> #N/A | I4676: =VLOOKUP(D4676,SubCategorias!B:C,2,FALSE) -> #N/A
A4677: 0189/B3CR | B4677: 0189/B3 CR - JUEGO MONOCOMANDO FLOW (B3) PARA BIDET FV | E4677: https://res.cloudinary.com/riqra/image/upload/v1534706090/saas/resources/placeholders/product.png | F4677: 0 | G4677: 118.12 | H4677: =VLOOKUP(C4677,Categorias!B:C,2,FALSE) -> #N/A | I4677: =VLOOKUP(D4677,SubCategorias!B:C,2,FALSE) -> #N/A
A4678: 0600.13.BBR | B4678: 0600.13.B BR - VALVULA COMPUERTA (ESCLUSA) BR 1/2" FV | E4678: https://res.cloudinary.com/riqra/image/upload/v1534706090/saas/resources/placeholders/product.png | F4678: 319 | G4678: 8.51 | H4678: =VLOOKUP(C4678,Categorias!B:C,2,FALSE) -> #N/A | I4678: =VLOOKUP(D4678,SubCategorias!B:C,2,FALSE) -> #N/A
A4679: 0600.19.BBR | B4679: 0600.19.B BR - VALVULA COMPUERTA (ESCLUSA) BR 3/4" FV | E4679: https://res.cloudinary.com/riqra/image/upload/v1534706090/saas/resources/placeholders/product.png | F4679: 85 | G4679: 11.91 | H4679: =VLOOKUP(C4679,Categorias!B:C,2,FALSE) -> #N/A | I4679: =VLOOKUP(D4679,SubCategorias!B:C,2,FALSE) -> #N/A
A4680: 23200105AM | B4680: 23200105 AM - CABLE FLEXIBLE #14 THHN/THWN AMARILLO 100MTS INCABLE | E4680: https://res.cloudinary.com/riqra/image/upload/v1534706090/saas/resources/placeholders/product.png | F4680: 90 | G4680: 34.76 | H4680: =VLOOKUP(C4680,Categorias!B:C,2,FALSE) -> #N/A | I4680: =VLOOKUP(D4680,SubCategorias!B:C,2,FALSE) -> #N/A
A4681: CAN-PVC15X10 | B4681: CAN-PVC 15X10 - CANALETA ADHESIVA 15MMX10MMX2M PROW | E4681: https://res.cloudinary.com/riqra/image/upload/v1534706090/saas/resources/placeholders/product.png | F4681: 3505 | G4681: 0.77 | H4681: =VLOOKUP(C4681,Categorias!B:C,2,FALSE) -> #N/A | I4681: =VLOOKUP(D4681,SubCategorias!B:C,2,FALSE) -> #N/A
A4682: CAN-PVC20X10 | B4682: CAN-PVC 20X10 - CANALETA ADHESIVA 20MMX10MMX2M PROW | E4682: https://res.cloudinary.com/riqra/image/upload/v1534706090/saas/resources/placeholders/product.png | F4682: 4994 | G4682: 0.88 | H4682: =VLOOKUP(C4682,Categorias!B:C,2,FALSE) -> #N/A | I4682: =VLOOKUP(D4682,SubCategorias!B:C,2,FALSE) -> #N/A
A4683: CAN-PVC24X14 | B4683: CAN-PVC 24X14 - CANALETA ADHESIVA 24MMX14MMX2M PROW | E4683: https://res.cloudinary.com/riqra/image/upload/v1534706090/saas/resources/placeholders/product.png | F4683: 677 | G4683: 1.39 | H4683: =VLOOKUP(C4683,Categorias!B:C,2,FALSE) -> #N/A | I4683: =VLOOKUP(D4683,SubCategorias!B:C,2,FALSE) -> #N/A
A4684: CAN-PVC39X19 | B4684: CAN-PVC 39X19 - CANALETA ADHESIVA 39MMX19MMX2M PROW | E4684: https://res.cloudinary.com/riqra/image/upload/v1534706090/saas/resources/placeholders/product.png | F4684: 1007 | G4684: 1.97 | H4684: =VLOOKUP(C4684,Categorias!B:C,2,FALSE) -> #N/A | I4684: =VLOOKUP(D4684,SubCategorias!B:C,2,FALSE) -> #N/A
A4685: E103.15.27.0DH | B4685: E103.15.27.0 DH - CABEZA ALTA 15 LATERAL ARMADA FV | E4685: https://res.cloudinary.com/riqra/image/upload/v1534706090/saas/resources/placeholders/product.png | F4685: 22 | G4685: 10.34 | H4685: =VLOOKUP(C4685,Categorias!B:C,2,FALSE) -> #N/A | I4685: =VLOOKUP(D4685,SubCategorias!B:C,2,FALSE) -> #N/A
... A4789: 16030 | B4789: 16030 - # BISAGRA OMEGA LATONADA (PARES) | E4789: https://res.cloudinary.com/riqra/image/upload/v1534706090/saas/resources/placeholders/product.png | F4789: 0 | G4789: 0.88 | H4789: =VLOOKUP(C4789,Categorias!B:C,2,FALSE) -> #N/A | I4789: =VLOOKUP(D4789,SubCategorias!B:C,2,FALSE) -> #N/A
A4790: 17178 | B4790: 17178 - VALVULA COMPUERTA 1/2 RED WHITE | C4790: Plomería | D4790: Valvulas | E4790: https://res.cloudinary.com/riqra/image/upload/v1671052630/sellers/7/ociiqunmlgytwnqqf6ed.png | F4790: 13 | G4790: 12.61 | H4790: =VLOOKUP(C4790,Categorias!B:C,2,FALSE) -> 706 | I4790: =VLOOKUP(D4790,SubCategorias!B:C,2,FALSE) -> 0
A4791: 17179 | B4791: 17179 - VALVULA COMPUERTA 3/4 RED WHITE | C4791: Plomería | D4791: Valvulas | E4791: https://res.cloudinary.com/riqra/image/upload/v1671052630/sellers/8/ukqflt6xnpknb9wwrj1f.png | F4791: 17 | G4791: 17.62 | H4791: =VLOOKUP(C4791,Categorias!B:C,2,FALSE) -> 706 | I4791: =VLOOKUP(D4791,SubCategorias!B:C,2,FALSE) -> 0
A4792: 17180 | B4792: 17180 - VALVULA COMPUERTA 1 RED WHITE | C4792: Plomería | D4792: Valvulas | E4792: https://res.cloudinary.com/riqra/image/upload/v1671052630/sellers/9/wjre9whtvq8zzuksjmvs.png | F4792: 4 | G4792: 28.07 | H4792: =VLOOKUP(C4792,Categorias!B:C,2,FALSE) -> 706 | I4792: =VLOOKUP(D4792,SubCategorias!B:C,2,FALSE) -> 0
A4793: 17191 | B4793: 17191 - VALVULA CHEQUE HORIZONTAL 1/2 RED WHITE | C4793: Plomería | D4793: Valvulas | E4793: https://res.cloudinary.com/riqra/image/upload/v1671052630/sellers/10/alnmrh1kwofcywx6sj5r.png | F4793: 50 | G4793: 13.29 | H4793: =VLOOKUP(C4793,Categorias!B:C,2,FALSE) -> 706 | I4793: =VLOOKUP(D4793,SubCategorias!B:C,2,FALSE) -> 0
A4794: 17192 | B4794: 17192 - VALVULA CHEQUE HORIZONTAL 3/4 RED WHITE | C4794: Plomería | D4794: Valvulas | E4794: https://res.cloudinary.com/riqra/image/upload/v1671052630/sellers/11/fkzci92ijmkiek3jivlr.png | F4794: 2 | G4794: 19.17 | H4794: =VLOOKUP(C4794,Categorias!B:C,2,FALSE) -> 706 | I4794: =VLOOKUP(D4794,SubCategorias!B:C,2,FALSE) -> 0
A4795: 17193 | B4795: 17193 - VALVULA CHEQUE HORIZONTAL 1 RED WHITE | C4795: Plomería | D4795: Valvulas | E4795: https://res.cloudinary.com/riqra/image/upload/v1671052630/sellers/12/u86zce7gtdmxj4s6udh8.png | F4795: 0 | G4795: 29.75 | H4795: =VLOOKUP(C4795,Categorias!B:C,2,FALSE) -> 706 | I4795: =VLOOKUP(D4795,SubCategorias!B:C,2,FALSE) -> 0
A4796: 17303 | B4796: 17303 - CERRADURA SOBREPONER 50 MM 7502 VIRO | E4796: https://res.cloudinary.com/riqra/image/upload/v1671052630/sellers/13/tquetreakavtalntjlej.png | F4796: 10 | G4796: 42.51 | H4796: =VLOOKUP(C4796,Categorias!B:C,2,FALSE) -> #N/A | I4796: =VLOOKUP(D4796,SubCategorias!B:C,2,FALSE) -> #N/A
A4797: 17304 | B4797: 17304 - CERRADURA SOBREPONER 60 MM 7503 VIRO | E4797: https://res.cloudinary.com/riqra/image/upload/v1671052630/sellers/14/xq5hbrmdsu4rhrwg3rxf.png | F4797: 7 | G4797: 42.94 | H4797: =VLOOKUP(C4797,Categorias!B:C,2,FALSE) -> #N/A | I4797: =VLOOKUP(D4797,SubCategorias!B:C,2,FALSE) -> #N/A
A4798: 17388 | B4798: 17388 - CANDADO 20MM 551 FAI BY VIRO | E4798: https://res.cloudinary.com/riqra/image/upload/v1671052632/sellers/0/p1pa2d1py4piwfxzsg13.png | F4798: 24 | G4798: 3.67 | H4798: =VLOOKUP(C4798,Categorias!B:C,2,FALSE) -> #N/A | I4798: =VLOOKUP(D4798,SubCategorias!B:C,2,FALSE) -> #N/A
A4799: 17389 | B4799: 17389 - CANDADO 25MM 552 FAI BY VIRO | E4799: https://res.cloudinary.com/riqra/image/upload/v1671052632/sellers/1/yow05jkuebcaqcnr7yby.png | F4799: 42 | G4799: 3.67 | H4799: =VLOOKUP(C4799,Categorias!B:C,2,FALSE) -> #N/A | I4799: =VLOOKUP(D4799,SubCategorias!B:C,2,FALSE) -> #N/A
A4800: 17390 | B4800: 17390 - CANDADO 30MM 553 FAI BY VIRO | E4800: https://res.cloudinary.com/riqra/image/upload/v1534706090/saas/resources/placeholders/product.png | F4800: 12 | G4800: 5.78 | H4800: =VLOOKUP(C4800,Categorias!B:C,2,FALSE) -> #N/A | I4800: =VLOOKUP(D4800,SubCategorias!B:C,2,FALSE) -> #N/A
A4801: 17391 | B4801: 17391 - CANDADO 40MM 554 FAI BY VIRO | E4801: https://res.cloudinary.com/riqra/image/upload/v1671052632/sellers/2/qzvujptt8jgiqnhs3ehe.png | F4801: 0 | G4801: 7.92 | H4801: =VLOOKUP(C4801,Categorias!B:C,2,FALSE) -> #N/A | I4801: =VLOOKUP(D4801,SubCategorias!B:C,2,FALSE) -> #N/A
A4802: 17392 | B4802: 17392 - CANDADO 50MM 555 FAI BY VIRO | E4802: https://res.cloudinary.com/riqra/image/upload/v1671052632/sellers/3/vrsjil5hydalltrnzzoa.png | F4802: 20 | G4802: 15.34 | H4802: =VLOOKUP(C4802,Categorias!B:C,2,FALSE) -> #N/A | I4802: =VLOOKUP(D4802,SubCategorias!B:C,2,FALSE) -> #N/A
...

Sheet Categorias
A1: Cod | B1: Categorias
A2: 1 | B2: Material Eléctrico | C2: 694
A3: 2 | B3: Acabados | C3: 690
A4: 3 | B4: Construcción | C4: 703
A5: 4 | B5: Pinturas y complementos | C5: 705
A6: 5 | B6: Seguridad Industrial | C6: 704
A7: 6 | B7: Herramientas Manuales | C7: 741
A8: 7 | B8: Cerrajería | C8: 701
A9: 8 | B9: Plomería | C9: 706
A10: 9 | B10: Ferretería | C10: 742
A11: 10 | B11: Limpieza | C11: 743
A12: 11 | B12: Herramientas eléctricas & Accesorios | C12: 702
A13: 12 | B13: Automotriz | C13: 744
... A15: 14 | B15: Gypsum & Tumbados | C15: 746

Sheet SubCategorias
A1: Codigo | B1: SubCategoria | C1: Relacion
A2: 1 | B2: Cables | C2: 1
A3: 2 | B3: Ceramica de piso
A4: 3 | B4: Impermeabilizantes
A5: 4 | B5: Empastes
A6: 5 | B6: Brochas
A7: 6 | B7: Guantes
A8: 7 | B8: Otros
A9: 8 | B9: Tubería Conduit Metálica (EMT)
A10: 9 | B10: Palas
A11: 10 | B11: Limas
A12: 11 | B12: Llaves
A13: 12 | B13: Tomacorrientes
A14: 13 | B14: Pomos
... A181: 180 | B181: Cabos|Ferretería

Sheet Relacion
A1: Relacion | B1: Cat | C1: Sub
A2: =VLOOKUP(B2,Categorias!B:C,2,FALSE) -> 690 | B2: Acabados | C2: Bloque de Vidrio
A3: =VLOOKUP(B3,Categorias!B:C,2,FALSE) -> 690 | B3: Acabados | C3: Ceramica de pared
A4: =VLOOKUP(B4,Categorias!B:C,2,FALSE) -> 690 | B4: Acabados | C4: Ceramica de piso
A5: =VLOOKUP(B5,Categorias!B:C,2,FALSE) -> 690 | B5: Acabados | C5: Duchas Electricas
A6: =VLOOKUP(B6,Categorias!B:C,2,FALSE) -> 690 | B6: Acabados | C6: Fregaderos
A7: =VLOOKUP(B7,Categorias!B:C,2,FALSE) -> 690 | B7: Acabados | C7: Granito
A8: =VLOOKUP(B8,Categorias!B:C,2,FALSE) -> 690 | B8: Acabados | C8: Griferia
A9: =VLOOKUP(B9,Categorias!B:C,2,FALSE) -> 690 | B9: Acabados | C9: Lavamanos
A10: =VLOOKUP(B10,Categorias!B:C,2,FALSE) -> 690 | B10: Acabados | C10: Porcelana para empore
A11: =VLOOKUP(B11,Categorias!B:C,2,FALSE) -> 690 | B11: Acabados | C11: Porcelanato
A12: =VLOOKUP(B12,Categorias!B:C,2,FALSE) -> 690 | B12: Acabados | C12: Rejillas
A13: =VLOOKUP(B13,Categorias!B:C,2,FALSE) -> 690 | B13: Acabados | C13: Sanitarios
... A236: =VLOOKUP(B236,Categorias!B:C,2,FALSE) -> 704 | B236: Seguridad Industrial | C236: Guantes
